Collecting pip
  Downloading https://files.pythonhosted.org/packages/07/51/2c0959c5adf988c44d9e1e0d940f5b074516ecc87e96b1af25f59de9ba38/pip-23.0.1-py3-none-any.whl (2.1MB)
ERROR: Exception:
Traceback (most recent call last):
  File "/home/yangyizhou/.local/share/pypoetry/venv/lib/python3.8/site-packages/pip/_vendor/urllib3/response.py", line 397, in _error_catcher
    yield
  File "/home/yangyizhou/.local/share/pypoetry/venv/lib/python3.8/site-packages/pip/_vendor/urllib3/response.py", line 479, in read
    data = self._fp.read(amt)
  File "/home/yangyizhou/.local/share/pypoetry/venv/lib/python3.8/site-packages/pip/_vendor/cachecontrol/filewrapper.py", line 62, in read
    data = self.__fp.read(amt)
  File "/home/yangyizhou/software/miniconda3/envs/rl4red/lib/python3.8/http/client.py", line 454, in read
    n = self.readinto(b)
  File "/home/yangyizhou/software/miniconda3/envs/rl4red/lib/python3.8/http/client.py", line 498, in readinto
    n = self.fp.readinto(b)
  File "/home/yangyizhou/software/miniconda3/envs/rl4red/lib/python3.8/socket.py", line 669, in readinto
    return self._sock.recv_into(b)
  File "/home/yangyizhou/software/miniconda3/envs/rl4red/lib/python3.8/ssl.py", line 1241, in recv_into
    return self.read(nbytes, buffer)
  File "/home/yangyizhou/software/miniconda3/envs/rl4red/lib/python3.8/ssl.py", line 1099, in read
    return self._sslobj.read(len, buffer)
socket.timeout: The read operation timed out

During handling of the above exception, another exception occurred:

Traceback (most recent call last):
  File "/home/yangyizhou/.local/share/pypoetry/venv/lib/python3.8/site-packages/pip/_internal/cli/base_command.py", line 188, in main
    status = self.run(options, args)
  File "/home/yangyizhou/.local/share/pypoetry/venv/lib/python3.8/site-packages/pip/_internal/commands/install.py", line 345, in run
    resolver.resolve(requirement_set)
  File "/home/yangyizhou/.local/share/pypoetry/venv/lib/python3.8/site-packages/pip/_internal/legacy_resolve.py", line 196, in resolve
    self._resolve_one(requirement_set, req)
  File "/home/yangyizhou/.local/share/pypoetry/venv/lib/python3.8/site-packages/pip/_internal/legacy_resolve.py", line 359, in _resolve_one
    abstract_dist = self._get_abstract_dist_for(req_to_install)
  File "/home/yangyizhou/.local/share/pypoetry/venv/lib/python3.8/site-packages/pip/_internal/legacy_resolve.py", line 305, in _get_abstract_dist_for
    abstract_dist = self.preparer.prepare_linked_requirement(
  File "/home/yangyizhou/.local/share/pypoetry/venv/lib/python3.8/site-packages/pip/_internal/operations/prepare.py", line 195, in prepare_linked_requirement
    unpack_url(
  File "/home/yangyizhou/.local/share/pypoetry/venv/lib/python3.8/site-packages/pip/_internal/download.py", line 1058, in unpack_url
    unpack_http_url(
  File "/home/yangyizhou/.local/share/pypoetry/venv/lib/python3.8/site-packages/pip/_internal/download.py", line 920, in unpack_http_url
    from_path, content_type = _download_http_url(link,
  File "/home/yangyizhou/.local/share/pypoetry/venv/lib/python3.8/site-packages/pip/_internal/download.py", line 1152, in _download_http_url
    _download_url(resp, link, content_file, hashes, progress_bar)
  File "/home/yangyizhou/.local/share/pypoetry/venv/lib/python3.8/site-packages/pip/_internal/download.py", line 861, in _download_url
    hashes.check_against_chunks(downloaded_chunks)
  File "/home/yangyizhou/.local/share/pypoetry/venv/lib/python3.8/site-packages/pip/_internal/utils/hashes.py", line 75, in check_against_chunks
    for chunk in chunks:
  File "/home/yangyizhou/.local/share/pypoetry/venv/lib/python3.8/site-packages/pip/_internal/download.py", line 829, in written_chunks
    for chunk in chunks:
  File "/home/yangyizhou/.local/share/pypoetry/venv/lib/python3.8/site-packages/pip/_internal/utils/ui.py", line 156, in iter
    for x in it:
  File "/home/yangyizhou/.local/share/pypoetry/venv/lib/python3.8/site-packages/pip/_internal/download.py", line 794, in resp_read
    for chunk in resp.raw.stream(
  File "/home/yangyizhou/.local/share/pypoetry/venv/lib/python3.8/site-packages/pip/_vendor/urllib3/response.py", line 531, in stream
    data = self.read(amt=amt, decode_content=decode_content)
  File "/home/yangyizhou/.local/share/pypoetry/venv/lib/python3.8/site-packages/pip/_vendor/urllib3/response.py", line 496, in read
    raise IncompleteRead(self._fp_bytes_read, self.length_remaining)
  File "/home/yangyizhou/software/miniconda3/envs/rl4red/lib/python3.8/contextlib.py", line 131, in __exit__
    self.gen.throw(type, value, traceback)
  File "/home/yangyizhou/.local/share/pypoetry/venv/lib/python3.8/site-packages/pip/_vendor/urllib3/response.py", line 402, in _error_catcher
    raise ReadTimeoutError(self._pool, None, 'Read timed out.')
pip._vendor.urllib3.exceptions.ReadTimeoutError: HTTPSConnectionPool(host='files.pythonhosted.org', port=443): Read timed out.

Traceback:

  File "<stdin>", line 919, in main
  File "<stdin>", line 550, in run
  File "<stdin>", line 571, in install
  File "/home/yangyizhou/software/miniconda3/envs/rl4red/lib/python3.8/contextlib.py", line 113, in __enter__
    return next(self.gen)
  File "<stdin>", line 643, in make_env
  File "<stdin>", line 629, in make_env
  File "<stdin>", line 344, in make
  File "<stdin>", line 367, in pip
  File "<stdin>", line 364, in python
  File "<stdin>", line 357, in run
